[2024-09-10T02:15:14.414+0800] {local_task_job_runner.py:123} INFO - ::group::Pre task execution logs
[2024-09-10T02:15:14.418+0800] {taskinstance.py:2612} INFO - Dependencies all met for dep_context=non-requeueable deps ti=<TaskInstance: casia-hwdb_elt.download_casia-hwdb_7 manual__2024-09-09T17:59:34.080448+00:00 [queued]>
[2024-09-10T02:15:14.421+0800] {taskinstance.py:2612} INFO - Dependencies all met for dep_context=requeueable deps ti=<TaskInstance: casia-hwdb_elt.download_casia-hwdb_7 manual__2024-09-09T17:59:34.080448+00:00 [queued]>
[2024-09-10T02:15:14.421+0800] {taskinstance.py:2865} INFO - Starting attempt 3 of 4
[2024-09-10T02:15:14.425+0800] {taskinstance.py:2888} INFO - Executing <Task(PythonOperator): download_casia-hwdb_7> on 2024-09-09 17:59:34.080448+00:00
[2024-09-10T02:15:14.431+0800] {logging_mixin.py:190} WARNING - /Users/erniesg/.pyenv/versions/3.12.5/envs/letters_home/lib/python3.12/site-packages/airflow/task/task_runner/standard_task_runner.py:70 DeprecationWarning: This process (pid=69666) is multi-threaded, use of fork() may lead to deadlocks in the child.
[2024-09-10T02:15:14.432+0800] {standard_task_runner.py:72} INFO - Started process 69667 to run task
[2024-09-10T02:15:14.431+0800] {standard_task_runner.py:104} INFO - Running: ['airflow', 'tasks', 'run', 'casia-hwdb_elt', 'download_casia-hwdb_7', 'manual__2024-09-09T17:59:34.080448+00:00', '--job-id', '38', '--raw', '--subdir', 'DAGS_FOLDER/elt.py', '--cfg-path', '/var/folders/3n/sh024_795c590k086c59jsw00000gn/T/tmpbsjb_asv']
[2024-09-10T02:15:14.432+0800] {standard_task_runner.py:105} INFO - Job 38: Subtask download_casia-hwdb_7
[2024-09-10T02:15:14.447+0800] {task_command.py:467} INFO - Running <TaskInstance: casia-hwdb_elt.download_casia-hwdb_7 manual__2024-09-09T17:59:34.080448+00:00 [running]> on host chens-macbook-pro.local
[2024-09-10T02:15:14.469+0800] {taskinstance.py:3131} INFO - Exporting env vars: AIRFLOW_CTX_DAG_OWNER='airflow' AIRFLOW_CTX_DAG_ID='casia-hwdb_elt' AIRFLOW_CTX_TASK_ID='download_casia-hwdb_7' AIRFLOW_CTX_EXECUTION_DATE='2024-09-09T17:59:34.080448+00:00' AIRFLOW_CTX_TRY_NUMBER='3' AIRFLOW_CTX_DAG_RUN_ID='manual__2024-09-09T17:59:34.080448+00:00'
[2024-09-10T02:15:14.469+0800] {logging_mixin.py:190} INFO - Task instance is in running state
[2024-09-10T02:15:14.469+0800] {logging_mixin.py:190} INFO -  Previous state of the Task instance: queued
[2024-09-10T02:15:14.469+0800] {logging_mixin.py:190} INFO - Current task name:download_casia-hwdb_7 state:running start_date:2024-09-09 18:15:14.418593+00:00
[2024-09-10T02:15:14.470+0800] {logging_mixin.py:190} INFO - Dag name:casia-hwdb_elt and current dag run status:running
[2024-09-10T02:15:14.470+0800] {taskinstance.py:731} INFO - ::endgroup::
[2024-09-10T02:15:14.471+0800] {taskinstance.py:3310} ERROR - Task failed with exception
Traceback (most recent call last):
  File "/Users/erniesg/.pyenv/versions/3.12.5/envs/letters_home/lib/python3.12/site-packages/airflow/models/taskinstance.py", line 767, in _execute_task
    result = _execute_callable(context=context, **execute_callable_kwargs)
             ^^^^^^^^^^^^^^^^^^^^^^^^^^^^^^^^^^^^^^^^^^^^^^^^^^^^^^^^^^^^^
  File "/Users/erniesg/.pyenv/versions/3.12.5/envs/letters_home/lib/python3.12/site-packages/airflow/models/taskinstance.py", line 733, in _execute_callable
    return ExecutionCallableRunner(
           ^^^^^^^^^^^^^^^^^^^^^^^^
  File "/Users/erniesg/.pyenv/versions/3.12.5/envs/letters_home/lib/python3.12/site-packages/airflow/utils/operator_helpers.py", line 252, in run
    return self.func(*args, **kwargs)
           ^^^^^^^^^^^^^^^^^^^^^^^^^^
  File "/Users/erniesg/.pyenv/versions/3.12.5/envs/letters_home/lib/python3.12/site-packages/airflow/models/baseoperator.py", line 406, in wrapper
    return func(self, *args, **kwargs)
           ^^^^^^^^^^^^^^^^^^^^^^^^^^^
  File "/Users/erniesg/.pyenv/versions/3.12.5/envs/letters_home/lib/python3.12/site-packages/airflow/operators/python.py", line 238, in execute
    return_value = self.execute_callable()
                   ^^^^^^^^^^^^^^^^^^^^^^^
  File "/Users/erniesg/.pyenv/versions/3.12.5/envs/letters_home/lib/python3.12/site-packages/airflow/operators/python.py", line 256, in execute_callable
    return runner.run(*self.op_args, **self.op_kwargs)
           ^^^^^^^^^^^^^^^^^^^^^^^^^^^^^^^^^^^^^^^^^^^
  File "/Users/erniesg/.pyenv/versions/3.12.5/envs/letters_home/lib/python3.12/site-packages/airflow/utils/operator_helpers.py", line 252, in run
    return self.func(*args, **kwargs)
           ^^^^^^^^^^^^^^^^^^^^^^^^^^
  File "/Users/erniesg/code/erniesg/if-letters-home-could-sing/pipeline/dags/elt.py", line 43, in process_download
    if check_s3_object_exists(s3_bucket, s3_key):
       ^^^^^^^^^^^^^^^^^^^^^^^^^^^^^^^^^^^^^^^^^
  File "/Users/erniesg/code/erniesg/if-letters-home-could-sing/pipeline/helpers/s3.py", line 30, in check_s3_object_exists
    s3_client.head_object(Bucket=bucket, Key=s3_key)
  File "/Users/erniesg/.pyenv/versions/3.12.5/envs/letters_home/lib/python3.12/site-packages/botocore/client.py", line 569, in _api_call
    return self._make_api_call(operation_name, kwargs)
           ^^^^^^^^^^^^^^^^^^^^^^^^^^^^^^^^^^^^^^^^^^^
  File "/Users/erniesg/.pyenv/versions/3.12.5/envs/letters_home/lib/python3.12/site-packages/botocore/client.py", line 964, in _make_api_call
    api_params = self._emit_api_params(
                 ^^^^^^^^^^^^^^^^^^^^^^
  File "/Users/erniesg/.pyenv/versions/3.12.5/envs/letters_home/lib/python3.12/site-packages/botocore/client.py", line 1083, in _emit_api_params
    self.meta.events.emit(
  File "/Users/erniesg/.pyenv/versions/3.12.5/envs/letters_home/lib/python3.12/site-packages/botocore/hooks.py", line 412, in emit
    return self._emitter.emit(aliased_event_name, **kwargs)
           ^^^^^^^^^^^^^^^^^^^^^^^^^^^^^^^^^^^^^^^^^^^^^^^^
  File "/Users/erniesg/.pyenv/versions/3.12.5/envs/letters_home/lib/python3.12/site-packages/botocore/hooks.py", line 256, in emit
    return self._emit(event_name, kwargs)
           ^^^^^^^^^^^^^^^^^^^^^^^^^^^^^^
  File "/Users/erniesg/.pyenv/versions/3.12.5/envs/letters_home/lib/python3.12/site-packages/botocore/hooks.py", line 239, in _emit
    response = handler(**kwargs)
               ^^^^^^^^^^^^^^^^^
  File "/Users/erniesg/.pyenv/versions/3.12.5/envs/letters_home/lib/python3.12/site-packages/botocore/handlers.py", line 297, in validate_bucket_name
    raise ParamValidationError(report=error_msg)
botocore.exceptions.ParamValidationError: Parameter validation failed:
Invalid bucket name "${S3_BUCKET_NAME}": Bucket name must match the regex "^[a-zA-Z0-9.\-_]{1,255}$" or be an ARN matching the regex "^arn:(aws).*:(s3|s3-object-lambda):[a-z\-0-9]*:[0-9]{12}:accesspoint[/:][a-zA-Z0-9\-.]{1,63}$|^arn:(aws).*:s3-outposts:[a-z\-0-9]+:[0-9]{12}:outpost[/:][a-zA-Z0-9\-]{1,63}[/:]accesspoint[/:][a-zA-Z0-9\-]{1,63}$"
[2024-09-10T02:15:14.474+0800] {logging_mixin.py:190} INFO - Task instance in failure state
[2024-09-10T02:15:14.474+0800] {logging_mixin.py:190} INFO - Task start:2024-09-09 18:15:14.418593+00:00 end:2024-09-09 18:15:14.474098+00:00 duration:0.055505
[2024-09-10T02:15:14.474+0800] {logging_mixin.py:190} INFO - Task:<Task(PythonOperator): download_casia-hwdb_7> dag:<DAG: casia-hwdb_elt> dagrun:<DagRun casia-hwdb_elt @ 2024-09-09 17:59:34.080448+00:00: manual__2024-09-09T17:59:34.080448+00:00, state:running, queued_at: 2024-09-09 17:59:34.086593+00:00. externally triggered: True>
[2024-09-10T02:15:14.474+0800] {logging_mixin.py:190} INFO - Failure caused by Parameter validation failed:
Invalid bucket name "${S3_BUCKET_NAME}": Bucket name must match the regex "^[a-zA-Z0-9.\-_]{1,255}$" or be an ARN matching the regex "^arn:(aws).*:(s3|s3-object-lambda):[a-z\-0-9]*:[0-9]{12}:accesspoint[/:][a-zA-Z0-9\-.]{1,63}$|^arn:(aws).*:s3-outposts:[a-z\-0-9]+:[0-9]{12}:outpost[/:][a-zA-Z0-9\-]{1,63}[/:]accesspoint[/:][a-zA-Z0-9\-]{1,63}$"
[2024-09-10T02:15:14.475+0800] {taskinstance.py:1225} INFO - Marking task as UP_FOR_RETRY. dag_id=casia-hwdb_elt, task_id=download_casia-hwdb_7, run_id=manual__2024-09-09T17:59:34.080448+00:00, execution_date=20240909T175934, start_date=20240909T181514, end_date=20240909T181514
[2024-09-10T02:15:14.480+0800] {taskinstance.py:340} INFO - ::group::Post task execution logs
[2024-09-10T02:15:14.480+0800] {standard_task_runner.py:124} ERROR - Failed to execute job 38 for task download_casia-hwdb_7 (Parameter validation failed:
Invalid bucket name "${S3_BUCKET_NAME}": Bucket name must match the regex "^[a-zA-Z0-9.\-_]{1,255}$" or be an ARN matching the regex "^arn:(aws).*:(s3|s3-object-lambda):[a-z\-0-9]*:[0-9]{12}:accesspoint[/:][a-zA-Z0-9\-.]{1,63}$|^arn:(aws).*:s3-outposts:[a-z\-0-9]+:[0-9]{12}:outpost[/:][a-zA-Z0-9\-]{1,63}[/:]accesspoint[/:][a-zA-Z0-9\-]{1,63}$"; 69667)
Traceback (most recent call last):
  File "/Users/erniesg/.pyenv/versions/3.12.5/envs/letters_home/lib/python3.12/site-packages/airflow/task/task_runner/standard_task_runner.py", line 117, in _start_by_fork
    ret = args.func(args, dag=self.dag)
          ^^^^^^^^^^^^^^^^^^^^^^^^^^^^^
  File "/Users/erniesg/.pyenv/versions/3.12.5/envs/letters_home/lib/python3.12/site-packages/airflow/cli/cli_config.py", line 49, in command
    return func(*args, **kwargs)
           ^^^^^^^^^^^^^^^^^^^^^
  File "/Users/erniesg/.pyenv/versions/3.12.5/envs/letters_home/lib/python3.12/site-packages/airflow/utils/cli.py", line 115, in wrapper
    return f(*args, **kwargs)
           ^^^^^^^^^^^^^^^^^^
  File "/Users/erniesg/.pyenv/versions/3.12.5/envs/letters_home/lib/python3.12/site-packages/airflow/cli/commands/task_command.py", line 483, in task_run
    task_return_code = _run_task_by_selected_method(args, _dag, ti)
                       ^^^^^^^^^^^^^^^^^^^^^^^^^^^^^^^^^^^^^^^^^^^^
  File "/Users/erniesg/.pyenv/versions/3.12.5/envs/letters_home/lib/python3.12/site-packages/airflow/cli/commands/task_command.py", line 256, in _run_task_by_selected_method
    return _run_raw_task(args, ti)
           ^^^^^^^^^^^^^^^^^^^^^^^
  File "/Users/erniesg/.pyenv/versions/3.12.5/envs/letters_home/lib/python3.12/site-packages/airflow/cli/commands/task_command.py", line 341, in _run_raw_task
    return ti._run_raw_task(
           ^^^^^^^^^^^^^^^^^
  File "/Users/erniesg/.pyenv/versions/3.12.5/envs/letters_home/lib/python3.12/site-packages/airflow/utils/session.py", line 97, in wrapper
    return func(*args, session=session, **kwargs)
           ^^^^^^^^^^^^^^^^^^^^^^^^^^^^^^^^^^^^^^
  File "/Users/erniesg/.pyenv/versions/3.12.5/envs/letters_home/lib/python3.12/site-packages/airflow/models/taskinstance.py", line 3004, in _run_raw_task
    return _run_raw_task(
           ^^^^^^^^^^^^^^
  File "/Users/erniesg/.pyenv/versions/3.12.5/envs/letters_home/lib/python3.12/site-packages/airflow/models/taskinstance.py", line 273, in _run_raw_task
    TaskInstance._execute_task_with_callbacks(
  File "/Users/erniesg/.pyenv/versions/3.12.5/envs/letters_home/lib/python3.12/site-packages/airflow/models/taskinstance.py", line 3158, in _execute_task_with_callbacks
    result = self._execute_task(context, task_orig)
             ^^^^^^^^^^^^^^^^^^^^^^^^^^^^^^^^^^^^^^
  File "/Users/erniesg/.pyenv/versions/3.12.5/envs/letters_home/lib/python3.12/site-packages/airflow/models/taskinstance.py", line 3182, in _execute_task
    return _execute_task(self, context, task_orig)
           ^^^^^^^^^^^^^^^^^^^^^^^^^^^^^^^^^^^^^^^
  File "/Users/erniesg/.pyenv/versions/3.12.5/envs/letters_home/lib/python3.12/site-packages/airflow/models/taskinstance.py", line 767, in _execute_task
    result = _execute_callable(context=context, **execute_callable_kwargs)
             ^^^^^^^^^^^^^^^^^^^^^^^^^^^^^^^^^^^^^^^^^^^^^^^^^^^^^^^^^^^^^
  File "/Users/erniesg/.pyenv/versions/3.12.5/envs/letters_home/lib/python3.12/site-packages/airflow/models/taskinstance.py", line 733, in _execute_callable
    return ExecutionCallableRunner(
           ^^^^^^^^^^^^^^^^^^^^^^^^
  File "/Users/erniesg/.pyenv/versions/3.12.5/envs/letters_home/lib/python3.12/site-packages/airflow/utils/operator_helpers.py", line 252, in run
    return self.func(*args, **kwargs)
           ^^^^^^^^^^^^^^^^^^^^^^^^^^
  File "/Users/erniesg/.pyenv/versions/3.12.5/envs/letters_home/lib/python3.12/site-packages/airflow/models/baseoperator.py", line 406, in wrapper
    return func(self, *args, **kwargs)
           ^^^^^^^^^^^^^^^^^^^^^^^^^^^
  File "/Users/erniesg/.pyenv/versions/3.12.5/envs/letters_home/lib/python3.12/site-packages/airflow/operators/python.py", line 238, in execute
    return_value = self.execute_callable()
                   ^^^^^^^^^^^^^^^^^^^^^^^
  File "/Users/erniesg/.pyenv/versions/3.12.5/envs/letters_home/lib/python3.12/site-packages/airflow/operators/python.py", line 256, in execute_callable
    return runner.run(*self.op_args, **self.op_kwargs)
           ^^^^^^^^^^^^^^^^^^^^^^^^^^^^^^^^^^^^^^^^^^^
  File "/Users/erniesg/.pyenv/versions/3.12.5/envs/letters_home/lib/python3.12/site-packages/airflow/utils/operator_helpers.py", line 252, in run
    return self.func(*args, **kwargs)
           ^^^^^^^^^^^^^^^^^^^^^^^^^^
  File "/Users/erniesg/code/erniesg/if-letters-home-could-sing/pipeline/dags/elt.py", line 43, in process_download
    if check_s3_object_exists(s3_bucket, s3_key):
       ^^^^^^^^^^^^^^^^^^^^^^^^^^^^^^^^^^^^^^^^^
  File "/Users/erniesg/code/erniesg/if-letters-home-could-sing/pipeline/helpers/s3.py", line 30, in check_s3_object_exists
    s3_client.head_object(Bucket=bucket, Key=s3_key)
  File "/Users/erniesg/.pyenv/versions/3.12.5/envs/letters_home/lib/python3.12/site-packages/botocore/client.py", line 569, in _api_call
    return self._make_api_call(operation_name, kwargs)
           ^^^^^^^^^^^^^^^^^^^^^^^^^^^^^^^^^^^^^^^^^^^
  File "/Users/erniesg/.pyenv/versions/3.12.5/envs/letters_home/lib/python3.12/site-packages/botocore/client.py", line 964, in _make_api_call
    api_params = self._emit_api_params(
                 ^^^^^^^^^^^^^^^^^^^^^^
  File "/Users/erniesg/.pyenv/versions/3.12.5/envs/letters_home/lib/python3.12/site-packages/botocore/client.py", line 1083, in _emit_api_params
    self.meta.events.emit(
  File "/Users/erniesg/.pyenv/versions/3.12.5/envs/letters_home/lib/python3.12/site-packages/botocore/hooks.py", line 412, in emit
    return self._emitter.emit(aliased_event_name, **kwargs)
           ^^^^^^^^^^^^^^^^^^^^^^^^^^^^^^^^^^^^^^^^^^^^^^^^
  File "/Users/erniesg/.pyenv/versions/3.12.5/envs/letters_home/lib/python3.12/site-packages/botocore/hooks.py", line 256, in emit
    return self._emit(event_name, kwargs)
           ^^^^^^^^^^^^^^^^^^^^^^^^^^^^^^
  File "/Users/erniesg/.pyenv/versions/3.12.5/envs/letters_home/lib/python3.12/site-packages/botocore/hooks.py", line 239, in _emit
    response = handler(**kwargs)
               ^^^^^^^^^^^^^^^^^
  File "/Users/erniesg/.pyenv/versions/3.12.5/envs/letters_home/lib/python3.12/site-packages/botocore/handlers.py", line 297, in validate_bucket_name
    raise ParamValidationError(report=error_msg)
botocore.exceptions.ParamValidationError: Parameter validation failed:
Invalid bucket name "${S3_BUCKET_NAME}": Bucket name must match the regex "^[a-zA-Z0-9.\-_]{1,255}$" or be an ARN matching the regex "^arn:(aws).*:(s3|s3-object-lambda):[a-z\-0-9]*:[0-9]{12}:accesspoint[/:][a-zA-Z0-9\-.]{1,63}$|^arn:(aws).*:s3-outposts:[a-z\-0-9]+:[0-9]{12}:outpost[/:][a-zA-Z0-9\-]{1,63}[/:]accesspoint[/:][a-zA-Z0-9\-]{1,63}$"
[2024-09-10T02:15:14.493+0800] {local_task_job_runner.py:266} INFO - Task exited with return code 1
[2024-09-10T02:15:14.502+0800] {taskinstance.py:3900} INFO - 0 downstream tasks scheduled from follow-on schedule check
[2024-09-10T02:15:14.502+0800] {local_task_job_runner.py:245} INFO - ::endgroup::
